<?xml version="1.0" ?>
<!-- =================================================================================== -->
<!-- |    This document was autogenerated by xacro from master.urdf.xacro              | -->
<!-- |    EDITING THIS FILE BY HAND IS NOT RECOMMENDED                                 | -->
<!-- =================================================================================== -->
<robot name="master" xmlns:controller="http://playerstage.sourceforge.net/gazebo/xmlschema/#controller" xmlns:interface="http://playerstage.sourceforge.net/gazebo/xmlschema/#interface" xmlns:sensor="http://playerstage.sourceforge.net/gazebo/xmlschema/#sensor" xmlns:xacro="http://www.ros.org/wiki/xacro">
  <link name="world"/>
  <material name="Schunk/LightGrey">
    <color rgba="0.7 0.7 0.7 1.0"/>
  </material>
  <material name="Schunk/DarkGrey">
    <color rgba="0.4 0.4 0.4 1.0"/>
  </material>
  <material name="Schunk/Black">
    <color rgba="0.0 0.0 0.0 1.0"/>
  </material>
  <material name="Schunk/DarkGolden">
    <color rgba="0.4 0.4 0.3 1.0"/>
  </material>
  <material name="Schunk/Blue">
    <color rgba="0.0 0.0 0.8 1.0"/>
  </material>
  <!--<xacro:include filename="$(find cob_description)/gazebo/gazebo.urdf.xacro" />-->
  <!-- GRIPPER 
  <xacro:include filename="$(find schunk_description)/urdf/pg70/pg70.urdf.xacro" />
	-->
  <!-- foot for arm
	<link name="base_link">
		<origin xyz="0 0 -10" rpy="0 0 0"/>
		<mass value="1000.0"/>	
		
		 <inertial>
		   <origin xyz="0 0 -10" rpy="0 0 0"/>
		   <mass value="1000.0"/>
		   <inertia ixx="100.0"  ixy="0"  ixz="0" iyy="100.0" iyz="0" izz="100.0" />
		</inertial>  
				
		<visual>
		   <origin xyz="0 0 .11" rpy="0 1 0" />
		   <geometry>
			  <box size="0.25 0.25 0.0125"/>
		   </geometry>
		   <material name="Schunk/DarkGrey" />
		</visual>

		<collision>
		   <origin xyz="0 0 0.11" rpy="0 1 0" />
		   <geometry>
			  <box size="0.25 0.25 0.0125"/>
		   </geometry>
		</collision> 
	
	</link>  -->
  <!-- joint between base_link and arm_0_link -->
  <joint name="arm_base_joint" type="fixed">
    <origin rpy="3.1415926 -1.25 3.1415926" xyz="0.5 0 0.35"/>
    <parent link="world"/>
    <child link="arm_base_link"/>
  </joint>
  <link name="arm_base_link">
    <inertial>
      <mass value="0.01"/>
      <origin xyz="0 0 0"/>
      <inertia ixx="0.001" ixy="0.0" ixz="0.0" iyy="0.001" iyz="0.0" izz="0.001"/>
    </inertial>
    <visual>
      <origin rpy="0 0 0" xyz="0 0 0.004"/>
      <geometry>
        <cylinder length="0.08" radius="0.045"/>
      </geometry>
      <material name="Schunk/DarkGolden"/>
    </visual>
    <collision>
      <origin rpy="0 0 0" xyz="0 0 0.005"/>
      <geometry>
        <box size="0.01 0.01 0.01"/>
      </geometry>
    </collision>
  </link>
  <!-- joint between arm_0_link and arm_1_link -->
  <joint name="arm_1_joint" type="revolute">
    <origin rpy="0 0 3.1415926" xyz="0 0 -0.250"/>
    <parent link="arm_base_link"/>
    <child link="arm_1_link"/>
    <axis xyz="0 0 1"/>
    <dynamics damping="10"/>
    <limit effort="370" lower="-3.1415" upper="3.1415" velocity="2.0"/>
    <!--limit effort="370" velocity="2.0" lower="-6.25" upper="6.25"/-->
    <!--safety_controller k_position="20" k_velocity="50" soft_lower_limit="${-6.25 + 0.01}" soft_upper_limit="${6.25 - 0.01}" /-->
  </joint>
  <link name="arm_1_link">
    <inertial>
      <mass value="0.01"/>
      <origin xyz="0 0 0"/>
      <inertia ixx="0.001" ixy="0.0" ixz="0.0" iyy="0.001" iyz="0.0" izz="0.001"/>
    </inertial>
    <visual>
      <origin rpy="0 0 0" xyz="0 0 0"/>
      <geometry>
        <mesh filename="package://schunk_description/meshes/lwa/lwa1.stl"/>
      </geometry>
      <material name="Schunk/DarkGolden"/>
    </visual>
    <collision>
      <origin rpy="0 0 0" xyz="0 0 0"/>
      <geometry>
        <mesh filename="package://schunk_description/meshes/lwa/lwa1.stl"/>
      </geometry>
    </collision>
  </link>
  <!-- joint between arm_1_link and arm_2_link -->
  <joint name="arm_2_joint" type="revolute">
    <origin rpy="1.5708 0 0" xyz="0 0 0"/>
    <parent link="arm_1_link"/>
    <child link="arm_2_link"/>
    <axis xyz="0 0 1"/>
    <dynamics damping="10"/>
    <limit effort="370" lower="-1.97" upper="1.97" velocity="2.0"/>
    <!--safety_controller k_position="20" k_velocity="50" soft_lower_limit="${-1.97 + 0.01}"   soft_upper_limit="${1.97 - 0.01}" /-->
  </joint>
  <link name="arm_2_link">
    <inertial>
      <mass value="0.01"/>
      <origin xyz="0 0 0"/>
      <inertia ixx="0.001" ixy="0.0" ixz="0.0" iyy="0.001" iyz="0.0" izz="0.001"/>
    </inertial>
    <visual>
      <origin rpy="0 0 0" xyz="0 0 0"/>
      <geometry>
        <mesh filename="package://schunk_description/meshes/lwa/lwa2.stl"/>
      </geometry>
      <material name="Schunk/DarkGolden"/>
    </visual>
    <collision>
      <origin rpy="0 0 0" xyz="0 0 0"/>
      <geometry>
        <mesh filename="package://schunk_description/meshes/lwa/lwa2.stl"/>
      </geometry>
    </collision>
  </link>
  <!-- joint between arm_2_link and arm_3_link -->
  <joint name="arm_3_joint" type="revolute">
    <origin rpy="-1.5708 0 0" xyz="0 -0.408 0"/>
    <parent link="arm_2_link"/>
    <child link="arm_3_link"/>
    <axis xyz="0 0 1"/>
    <dynamics damping="5"/>
    <limit effort="176" lower="-3.1415" upper="3.1415" velocity="2.0"/>
    <!--limit effort="176" velocity="2.0" lower="-6.25" upper="6.25"/-->
    <!--safety_controller k_position="20" k_velocity="25" soft_lower_limit="${-6.25 + 0.01}" soft_upper_limit="${6.25 - 0.01}" /-->
  </joint>
  <link name="arm_3_link">
    <inertial>
      <mass value="0.01"/>
      <origin xyz="0 0 0"/>
      <inertia ixx="0.001" ixy="0.0" ixz="0.0" iyy="0.001" iyz="0.0" izz="0.001"/>
    </inertial>
    <visual>
      <origin rpy="0 0 0" xyz="0 0 0"/>
      <geometry>
        <mesh filename="package://schunk_description/meshes/lwa/lwa3.stl"/>
      </geometry>
      <material name="Schunk/DarkGolden"/>
    </visual>
    <collision>
      <origin rpy="0 0 0" xyz="0 0 0"/>
      <geometry>
        <mesh filename="package://schunk_description/meshes/lwa/lwa3.stl"/>
      </geometry>
    </collision>
  </link>
  <!-- joint between arm_3_link and arm_4_link -->
  <joint name="arm_4_joint" type="revolute">
    <origin rpy="1.5708 0 0" xyz="0 0 0"/>
    <parent link="arm_3_link"/>
    <child link="arm_4_link"/>
    <axis xyz="0 0 1"/>
    <dynamics damping="5"/>
    <limit effort="176" lower="-1.97" upper="1.97" velocity="2.0"/>
    <!--safety_controller k_position="20" k_velocity="25" soft_lower_limit="${-1.97 + 0.01}" soft_upper_limit="${1.97 - 0.01}" /-->
  </joint>
  <link name="arm_4_link">
    <inertial>
      <mass value="0.01"/>
      <origin xyz="0 0 0"/>
      <inertia ixx="0.001" ixy="0.0" ixz="0.0" iyy="0.001" iyz="0.0" izz="0.001"/>
    </inertial>
    <visual>
      <origin rpy="0 0 0" xyz="0 0 0"/>
      <geometry>
        <mesh filename="package://schunk_description/meshes/lwa/lwa4.stl"/>
      </geometry>
      <material name="Schunk/DarkGolden"/>
    </visual>
    <collision>
      <origin rpy="0 0 0" xyz="0 0 0"/>
      <geometry>
        <mesh filename="package://schunk_description/meshes/lwa/lwa4.stl"/>
      </geometry>
    </collision>
  </link>
  <!-- joint between arm_4_link and arm_5_link -->
  <joint name="arm_5_joint" type="revolute">
    <origin rpy="-1.5708 0 0" xyz="0 -0.3165 0"/>
    <parent link="arm_4_link"/>
    <child link="arm_5_link"/>
    <axis xyz="0 0 1"/>
    <dynamics damping="5"/>
    <limit effort="41.6" lower="-3.1415" upper="3.1415" velocity="2.0"/>
    <!--limit effort="41.6" velocity="2.0" lower="-6.25" upper="6.25" /-->
    <!--safety_controller k_position="20" k_velocity="25" soft_lower_limit="${-6.25 + 0.01}" soft_upper_limit="${6.25 - 0.01}" /-->
  </joint>
  <link name="arm_5_link">
    <inertial>
      <mass value="0.01"/>
      <origin xyz="0 0 0"/>
      <inertia ixx="0.001" ixy="0.0" ixz="0.0" iyy="0.001" iyz="0.0" izz="0.001"/>
    </inertial>
    <visual>
      <origin rpy="0 0 0" xyz="0 0 0"/>
      <geometry>
        <mesh filename="package://schunk_description/meshes/lwa/lwa5.stl"/>
      </geometry>
      <material name="Schunk/DarkGolden"/>
    </visual>
    <collision>
      <origin rpy="0 0 0" xyz="0 0 0"/>
      <geometry>
        <mesh filename="package://schunk_description/meshes/lwa/lwa5.stl"/>
      </geometry>
    </collision>
  </link>
  <!-- joint between arm_5_link and arm_6_link -->
  <joint name="arm_6_joint" type="revolute">
    <origin rpy="1.5708 0 0" xyz="0 0 0"/>
    <parent link="arm_5_link"/>
    <child link="arm_6_link"/>
    <axis xyz="0 0 1"/>
    <dynamics damping="5"/>
    <limit effort="20.1" lower="-1.97" upper="1.97" velocity="2.0"/>
    <!--safety_controller k_position="20" k_velocity="25" soft_lower_limit="${-1.97 + 0.01}" soft_upper_limit="${1.97 - 0.01}" /-->
  </joint>
  <link name="arm_6_link">
    <inertial>
      <mass value="0.01"/>
      <origin xyz="0 0 0"/>
      <inertia ixx="0.001" ixy="0.0" ixz="0.0" iyy="0.001" iyz="0.0" izz="0.001"/>
    </inertial>
    <visual>
      <origin rpy="0 0 0" xyz="0 0 0"/>
      <geometry>
        <mesh filename="package://schunk_description/meshes/lwa/lwa6.stl"/>
      </geometry>
      <material name="Schunk/DarkGolden"/>
    </visual>
    <collision>
      <origin rpy="0 0 0" xyz="0 0 0"/>
      <geometry>
        <mesh filename="package://schunk_description/meshes/lwa/lwa6.stl"/>
      </geometry>
    </collision>
  </link>
  <!-- joint between arm_6_link and arm_7_link -->
  <joint name="arm_7_joint" type="revolute">
    <origin rpy="-1.5708 0 0" xyz="0 -0.1927 0"/>
    <parent link="arm_6_link"/>
    <child link="arm_7_link"/>
    <axis xyz="0 0 1"/>
    <dynamics damping="5"/>
    <limit effort="9.6" lower="-3.1415" upper="3.1415" velocity="2.0"/>
    <!--limit effort="9.6" velocity="2.0" lower="-6.25" upper="6.25" /-->
    <!--safety_controller k_position="20" k_velocity="25" soft_lower_limit="${-6.25 + 0.01}" soft_upper_limit="${6.25 - 0.01}" /-->
  </joint>
  <link name="arm_7_link">
    <inertial>
      <mass value="0.01"/>
      <origin xyz="0 0 0"/>
      <inertia ixx="0.001" ixy="0.0" ixz="0.0" iyy="0.001" iyz="0.0" izz="0.001"/>
    </inertial>
    <visual>
      <origin rpy="0 0 0" xyz="0 0 0"/>
      <geometry>
        <mesh filename="package://schunk_description/meshes/lwa/lwa7.stl"/>
      </geometry>
      <material name="Schunk/DarkGolden"/>
    </visual>
    <collision>
      <origin rpy="0 0 0" xyz="0 0 0"/>
      <geometry>
        <mesh filename="package://schunk_description/meshes/lwa/lwa7.stl"/>
      </geometry>
    </collision>
  </link>
  <gazebo reference="arm_0_link">
    <gravity>true</gravity>
    <self_collide>false</self_collide>
    <material value="Schunk/DarkGolden"/>
  </gazebo>
  <gazebo reference="arm_1_link">
    <gravity>true</gravity>
    <self_collide>false</self_collide>
    <material value="Schunk/DarkGolden"/>
  </gazebo>
  <gazebo reference="arm_2_link">
    <gravity>true</gravity>
    <self_collide>false</self_collide>
    <material value="Schunk/DarkGolden"/>
  </gazebo>
  <gazebo reference="arm_3_link">
    <gravity>true</gravity>
    <self_collide>false</self_collide>
    <material value="Schunk/DarkGolden"/>
  </gazebo>
  <gazebo reference="arm_4_link">
    <gravity>true</gravity>
    <self_collide>false</self_collide>
    <material value="Schunk/DarkGolden"/>
  </gazebo>
  <gazebo reference="arm_5_link">
    <gravity>true</gravity>
    <self_collide>false</self_collide>
    <material value="Schunk/DarkGolden"/>
  </gazebo>
  <gazebo reference="arm_6_link">
    <gravity>true</gravity>
    <self_collide>false</self_collide>
    <material value="Schunk/DarkGolden"/>
  </gazebo>
  <gazebo reference="arm_7_link">
    <gravity>true</gravity>
    <self_collide>false</self_collide>
    <material value="Schunk/DarkGolden"/>
  </gazebo>
  <transmission name="arm_1_trans">
    <type>transmission_interface/SimpleTransmission</type>
    <joint name="arm_1_joint">
      <hardwareInterface>PositionJointInterface</hardwareInterface>
      <hardwareInterface>VelocityJointInterface</hardwareInterface>
      <!--hardwareInterface>EffortJointInterface</hardwareInterface-->
    </joint>
    <actuator name="arm_1_motor">
      <mechanicalReduction>1</mechanicalReduction>
    </actuator>
  </transmission>
  <transmission name="arm_2_trans">
    <type>transmission_interface/SimpleTransmission</type>
    <joint name="arm_2_joint">
      <hardwareInterface>PositionJointInterface</hardwareInterface>
      <hardwareInterface>VelocityJointInterface</hardwareInterface>
      <!--hardwareInterface>EffortJointInterface</hardwareInterface-->
    </joint>
    <actuator name="arm_2_motor">
      <mechanicalReduction>1</mechanicalReduction>
    </actuator>
  </transmission>
  <transmission name="arm_3_trans">
    <type>transmission_interface/SimpleTransmission</type>
    <joint name="arm_3_joint">
      <hardwareInterface>PositionJointInterface</hardwareInterface>
      <hardwareInterface>VelocityJointInterface</hardwareInterface>
      <!--hardwareInterface>EffortJointInterface</hardwareInterface-->
    </joint>
    <actuator name="arm_3_motor">
      <mechanicalReduction>1</mechanicalReduction>
    </actuator>
  </transmission>
  <transmission name="arm_4_trans">
    <type>transmission_interface/SimpleTransmission</type>
    <joint name="arm_4_joint">
      <hardwareInterface>PositionJointInterface</hardwareInterface>
      <hardwareInterface>VelocityJointInterface</hardwareInterface>
      <!--hardwareInterface>EffortJointInterface</hardwareInterface-->
    </joint>
    <actuator name="arm_4_motor">
      <mechanicalReduction>1</mechanicalReduction>
    </actuator>
  </transmission>
  <transmission name="arm_5_trans">
    <type>transmission_interface/SimpleTransmission</type>
    <joint name="arm_5_joint">
      <hardwareInterface>PositionJointInterface</hardwareInterface>
      <hardwareInterface>VelocityJointInterface</hardwareInterface>
      <!--hardwareInterface>EffortJointInterface</hardwareInterface-->
    </joint>
    <actuator name="arm_5_motor">
      <mechanicalReduction>1</mechanicalReduction>
    </actuator>
  </transmission>
  <transmission name="arm_6_trans">
    <type>transmission_interface/SimpleTransmission</type>
    <joint name="arm_6_joint">
      <hardwareInterface>PositionJointInterface</hardwareInterface>
      <hardwareInterface>VelocityJointInterface</hardwareInterface>
      <!--hardwareInterface>EffortJointInterface</hardwareInterface-->
    </joint>
    <actuator name="arm_6_motor">
      <mechanicalReduction>1</mechanicalReduction>
    </actuator>
  </transmission>
  <transmission name="arm_7_trans">
    <type>transmission_interface/SimpleTransmission</type>
    <joint name="arm_7_joint">
      <hardwareInterface>PositionJointInterface</hardwareInterface>
      <hardwareInterface>VelocityJointInterface</hardwareInterface>
      <!--hardwareInterface>EffortJointInterface</hardwareInterface-->
    </joint>
    <actuator name="arm_7_motor">
      <mechanicalReduction>1</mechanicalReduction>
    </actuator>
  </transmission>
  <!-- ros_control plugin -->
  <gazebo>
    <plugin filename="libhwi_switch_gazebo_ros_control.so" name="ros_control">
      <robotNamespace>arm</robotNamespace>
      <filterJointsParam>joint_names</filterJointsParam>
    </plugin>
  </gazebo>
  <!-- GRIPPER
  <xacro:schunk_pg70 name="gripper" parent="arm_7_link" has_podest="false">
    <origin xyz="0 0 -.0075" rpy="3.1415926 0 0" />
  </xacro:schunk_pg70>
	 -->
  <material name="Blue">
    <color rgba="0.0 0.0 0.8 1.0"/>
  </material>
  <material name="Green">
    <color rgba="0.0 0.8 0.0 1.0"/>
  </material>
  <material name="Grey">
    <color rgba="0.6 0.6 0.6 1.0"/>
  </material>
  <material name="Grey2">
    <color rgba="0.9 0.9 0.9 1.0"/>
  </material>
  <material name="Red">
    <color rgba="0.8 0.0 0.0 1.0"/>
  </material>
  <material name="White">
    <color rgba="1.0 1.0 1.0 1.0"/>
  </material>
  <material name="Black">
    <color rgba="0.1 0.1 0.1 1.0"/>
  </material>
  <material name="LightGrey">
    <color rgba="0.6 0.6 0.6 1.0"/>
  </material>
  <link name="segway_base_link">
    <inertial>
      <mass value="90.0"/>
      <origin xyz="0.0 0.0 0.0"/>
      <inertia ixx="1.25" ixy="0.0" ixz="0.0" iyy="7.0" iyz="0.0" izz="8.0"/>
    </inertial>
    <visual>
      <origin rpy="0 0 0" xyz="0 0 0"/>
      <geometry>
        <mesh filename="package://rmp_description/meshes/rmp440le/base/base.stl" scale="0.001 0.001 0.001"/>
      </geometry>
      <material name="Grey"/>
    </visual>
    <collision>
      <origin rpy="0 0 0" xyz="0 0 0"/>
      <geometry>
        <mesh filename="package://rmp_description/meshes/rmp440le/base/base_collision.stl" scale="0.001 0.001 0.001"/>
      </geometry>
    </collision>
  </link>
  <joint name="base_footprint_joint" type="fixed">
    <origin rpy="0 0 0" xyz="0 0 0.2667"/>
    <child link="segway_base_link"/>
    <parent link="world"/>
  </joint>
  <joint name="left_front_wheel" type="continuous">
    <origin rpy="0 0 0" xyz="0.285748 0.33675 0.0"/>
    <parent link="segway_base_link"/>
    <child link="left_front_wheel_link"/>
    <axis xyz="0 1 0"/>
    <limit effort="6.5" velocity="10"/>
    <safety_controller k_velocity="10"/>
    <dynamics damping="1.0" friction="0.0"/>
  </joint>
  <link name="left_front_wheel_link">
    <inertial>
      <mass value="4.0"/>
      <origin xyz="0 0 0"/>
      <inertia ixx="0.08" ixy="0" ixz="0" iyy="0.14" iyz="0" izz="0.08"/>
    </inertial>
    <visual>
      <origin rpy="0 0 0" xyz="0 0 0"/>
      <geometry>
        <mesh filename="package://rmp_description/meshes/rmp440le/base/wheel.stl" scale="0.001 0.001 0.001"/>
      </geometry>
      <material name="Black"/>
    </visual>
    <collision>
      <origin rpy="0 0 0" xyz="0 0 0"/>
      <geometry>
        <mesh filename="package://rmp_description/meshes/rmp440le/base/wheel_collision.stl" scale="0.001 0.001 0.001"/>
      </geometry>
    </collision>
  </link>
  <joint name="left_rear_wheel" type="continuous">
    <origin rpy="0 0 0" xyz="-0.285748 0.33675 0.0"/>
    <parent link="segway_base_link"/>
    <child link="left_rear_wheel_link"/>
    <axis xyz="0 1 0"/>
    <limit effort="6.5" velocity="10"/>
    <safety_controller k_velocity="10"/>
    <dynamics damping="1.0" friction="0.0"/>
  </joint>
  <link name="left_rear_wheel_link">
    <inertial>
      <mass value="4.0"/>
      <origin xyz="0 0 0"/>
      <inertia ixx="0.08" ixy="0" ixz="0" iyy="0.14" iyz="0" izz="0.08"/>
    </inertial>
    <visual>
      <origin rpy="0 0 0" xyz="0 0 0"/>
      <geometry>
        <mesh filename="package://rmp_description/meshes/rmp440le/base/wheel.stl" scale="0.001 0.001 0.001"/>
      </geometry>
      <material name="Black"/>
    </visual>
    <collision>
      <origin rpy="0 0 0" xyz="0 0 0"/>
      <geometry>
        <mesh filename="package://rmp_description/meshes/rmp440le/base/wheel_collision.stl" scale="0.001 0.001 0.001"/>
      </geometry>
    </collision>
  </link>
  <joint name="right_front_wheel" type="continuous">
    <origin rpy="0 0 0" xyz="0.285748 -0.33675 0.0"/>
    <parent link="segway_base_link"/>
    <child link="right_front_wheel_link"/>
    <axis xyz="0 1 0"/>
    <limit effort="6.5" velocity="10"/>
    <safety_controller k_velocity="10"/>
    <dynamics damping="1.0" friction="0.0"/>
  </joint>
  <link name="right_front_wheel_link">
    <inertial>
      <mass value="4.0"/>
      <origin xyz="0 0 0"/>
      <inertia ixx="0.08" ixy="0" ixz="0" iyy="0.14" iyz="0" izz="0.08"/>
    </inertial>
    <visual>
      <origin rpy="0 0 3.14159265359" xyz="0 0 0"/>
      <geometry>
        <mesh filename="package://rmp_description/meshes/rmp440le/base/wheel.stl" scale="0.001 0.001 0.001"/>
      </geometry>
      <material name="Black"/>
    </visual>
    <collision>
      <origin rpy="0 0 3.14159265359" xyz="0 0 0"/>
      <geometry>
        <mesh filename="package://rmp_description/meshes/rmp440le/base/wheel_collision.stl" scale="0.001 0.001 0.001"/>
      </geometry>
    </collision>
  </link>
  <joint name="right_rear_wheel" type="continuous">
    <origin rpy="0 0 0" xyz="-0.285748 -0.33675 0.0"/>
    <parent link="segway_base_link"/>
    <child link="right_rear_wheel_link"/>
    <axis xyz="0 1 0"/>
    <limit effort="6.5" velocity="10"/>
    <safety_controller k_velocity="10"/>
    <dynamics damping="1.0" friction="0.0"/>
  </joint>
  <link name="right_rear_wheel_link">
    <inertial>
      <mass value="4.0"/>
      <origin xyz="0 0 0"/>
      <inertia ixx="0.08" ixy="0" ixz="0" iyy="0.14" iyz="0" izz="0.08"/>
    </inertial>
    <visual>
      <origin rpy="0 0 3.14159265359" xyz="0 0 0"/>
      <geometry>
        <mesh filename="package://rmp_description/meshes/rmp440le/base/wheel.stl" scale="0.001 0.001 0.001"/>
      </geometry>
      <material name="Black"/>
    </visual>
    <collision>
      <origin rpy="0 0 3.14159265359" xyz="0 0 0"/>
      <geometry>
        <mesh filename="package://rmp_description/meshes/rmp440le/base/wheel_collision.stl" scale="0.001 0.001 0.001"/>
      </geometry>
    </collision>
  </link>
  <joint name="arm_base_connector" type="fixed">
    <child link="arm_base_link"/>
    <parent link="world"/>
  </joint>
</robot>

